{
  "nbformat": 4,
  "nbformat_minor": 0,
  "metadata": {
    "colab": {
      "provenance": []
    },
    "kernelspec": {
      "name": "python3",
      "display_name": "Python 3"
    },
    "language_info": {
      "name": "python"
    }
  },
  "cells": [
    {
      "cell_type": "markdown",
      "source": [
        "# Exercice 7 : Journalisation des Exceptions"
      ],
      "metadata": {
        "id": "aY5XWsyiWMP1"
      }
    },
    {
      "cell_type": "code",
      "execution_count": 49,
      "metadata": {
        "id": "lW_zB5jeWCXs",
        "colab": {
          "base_uri": "https://localhost:8080/",
          "height": 383
        },
        "outputId": "2d640240-8083-4739-9c27-000ad60f3fe5"
      },
      "outputs": [
        {
          "output_type": "error",
          "ename": "ImportError",
          "evalue": "cannot import name 'log_error' from 'logging' (/usr/lib/python3.11/logging/__init__.py)",
          "traceback": [
            "\u001b[0;31m---------------------------------------------------------------------------\u001b[0m",
            "\u001b[0;31mImportError\u001b[0m                               Traceback (most recent call last)",
            "\u001b[0;32m<ipython-input-49-05f3f2e0cd2a>\u001b[0m in \u001b[0;36m<cell line: 0>\u001b[0;34m()\u001b[0m\n\u001b[0;32m----> 1\u001b[0;31m \u001b[0;32mfrom\u001b[0m \u001b[0mlogging\u001b[0m \u001b[0;32mimport\u001b[0m \u001b[0mlog_error\u001b[0m\u001b[0;34m\u001b[0m\u001b[0;34m\u001b[0m\u001b[0m\n\u001b[0m\u001b[1;32m      2\u001b[0m \u001b[0;34m\u001b[0m\u001b[0m\n\u001b[1;32m      3\u001b[0m \u001b[0;32mdef\u001b[0m \u001b[0mread_file\u001b[0m\u001b[0;34m(\u001b[0m\u001b[0mfilename\u001b[0m\u001b[0;34m)\u001b[0m\u001b[0;34m:\u001b[0m\u001b[0;34m\u001b[0m\u001b[0;34m\u001b[0m\u001b[0m\n\u001b[1;32m      4\u001b[0m     \u001b[0;32mtry\u001b[0m\u001b[0;34m:\u001b[0m\u001b[0;34m\u001b[0m\u001b[0;34m\u001b[0m\u001b[0m\n\u001b[1;32m      5\u001b[0m         \u001b[0;32mwith\u001b[0m \u001b[0mopen\u001b[0m\u001b[0;34m(\u001b[0m\u001b[0mfilename\u001b[0m\u001b[0;34m,\u001b[0m \u001b[0;34m'r'\u001b[0m\u001b[0;34m)\u001b[0m \u001b[0;32mas\u001b[0m \u001b[0mfile\u001b[0m\u001b[0;34m:\u001b[0m\u001b[0;34m\u001b[0m\u001b[0;34m\u001b[0m\u001b[0m\n",
            "\u001b[0;31mImportError\u001b[0m: cannot import name 'log_error' from 'logging' (/usr/lib/python3.11/logging/__init__.py)",
            "",
            "\u001b[0;31m---------------------------------------------------------------------------\u001b[0;32m\nNOTE: If your import is failing due to a missing package, you can\nmanually install dependencies using either !pip or !apt.\n\nTo view examples of installing some common dependencies, click the\n\"Open Examples\" button below.\n\u001b[0;31m---------------------------------------------------------------------------\u001b[0m\n"
          ],
          "errorDetails": {
            "actions": [
              {
                "action": "open_url",
                "actionText": "Open Examples",
                "url": "/notebooks/snippets/importing_libraries.ipynb"
              }
            ]
          }
        }
      ],
      "source": [
        "from logging import log_error\n",
        "\n",
        "def read_file(filename):\n",
        "    try:\n",
        "        with open(filename, 'r') as file:\n",
        "            return file.read()\n",
        "    except FileNotFoundError:\n",
        "        log_error(f\"Erreur : Le fichier '{filename}' est introuvable.\")\n",
        "        print(f\"Erreur : Le fichier '{filename}' est introuvable.\")\n",
        "    finally:\n",
        "        print(\"lecture termin√©e.\")\n",
        "\n",
        "# Test\n",
        "filename = \"fichier_inexistant.txt\"\n",
        "read_file(filename)\n"
      ]
    }
  ]
}